<?xml version="1.0"?>
<robot name="my_robot_arm" xmlns:xacro="http://www.ros.org/wiki/xacro">

    <!-- Define some constants -->
    <xacro:property name="arm_length" value="1.0" />
    <xacro:property name="arm_radius" value="0.05" />
    <xacro:property name="gripper_length" value="0.2" />
    <xacro:property name="gripper_radius" value="0.02" />

    <!-- Base link -->
    <link name="base_link">
        <visual>
            <geometry>
                <cylinder length="0.1" radius="0.1" />
            </geometry>
            <material name="blue" />
        </visual>
    </link>

    <!-- Joint 1 -->
    <joint name="joint1" type="revolute">
        <parent link="base_link" />
        <child link="link1" />
        <origin xyz="0 0 0.05" rpy="0 0 0" />
        <axis xyz="0 0 1" />
        <limit lower="-1.57" upper="1.57" effort="10" velocity="1" />
    </joint>

    <!-- Link 1 -->
    <link name="link1">
        <visual>
            <geometry>
                <cylinder length="${arm_length}" radius="${arm_radius}" />
            </geometry>
            <material name="green" />
        </visual>
    </link>

    <!-- Joint 2 -->
    <joint name="joint2" type="revolute">
        <parent link="link1" />
        <child link="link2" />
        <origin xyz="0 0 ${arm_length}" rpy="0 0 0" />
        <axis xyz="0 1 0" />
        <limit lower="-1.57" upper="1.57" effort="10" velocity="1" />
    </joint>

    <!-- Link 2 -->
    <link name="link2">
        <visual>
            <geometry>
                <cylinder length="${arm_length}" radius="${arm_radius}" />
            </geometry>
            <material name="red" />
        </visual>
    </link>

    <!-- Joint 3 -->
    <joint name="joint3" type="revolute">
        <parent link="link2" />
        <child link="link3" />
        <origin xyz="0 0 ${arm_length}" rpy="0 0 0" />
        <axis xyz="0 1 0" />
        <limit lower="-1.57" upper="1.57" effort="10" velocity="1" />
    </joint>

    <!-- Link 3 -->
    <link name="link3">
        <visual>
            <geometry>
                <cylinder length="${arm_length}" radius="${arm_radius}" />
            </geometry>
            <material name="yellow" />
        </visual>
    </link>

    <!-- Gripper Joint -->
    <joint name="gripper_joint" type="fixed">
        <parent link="link3" />
        <child link="gripper" />
        <origin xyz="0 0 ${arm_length}" rpy="0 0 0" />
    </joint>

    <!-- Gripper -->
    <link name="gripper">
        <visual>
            <geometry>
                <cylinder length="${gripper_length}" radius="${gripper_radius}" />
            </geometry>
            <material name="gray" />
        </visual>
    </link>

</robot>